Workbook
Name AccountList: #REF!
Name CountLanguage: #REF!
Name KritLanguage: #REF!
Name Language_Anlagenkat.: IF(#REF!="Deutsch",#REF!,IF(#REF!="English",#REF!))
Name Language_DeinvestAnlkat: IF(#REF!="Deutsch",#REF!,IF(#REF!="English",#REF!))
Name Language_DeinvestFinanz.: IF(#REF!="Deutsch",#REF!,IF(#REF!="English",#REF!))
Name Language_DeinvestInvkat.: IF(#REF!="Deutsch",#REF!,IF(#REF!="English",#REF!))
Name Language_Finanz: IF(#REF!="Deutsch",#REF!,IF(#REF!="English",#REF!))
Name Language_Investkat.: IF(#REF!="Deutsch",#REF!,IF(#REF!="English",#REF!))
Name Language_Verpflichtungsgrad: _xlfn.IFS(#REF!="Deutsch",#REF!,#REF!="English",#REF!)

Sheet P&L
A1: PreBo Statement of Profit and loss for the year Jan to June 2025 ( Amt T INR) | K1: PreBo Statement of Profit and loss for the year (YTD) June 2025 (Amt T INR)
A2: Particulars | B2: Notes | C2: Jan'25 | D2: Feb'25 | E2: Mar'25 | F2: Apr'25 | G2: May'25 | H2: Jun'25 | K2: Jan'25 | L2: YTD Feb'25 | M2: YTD Mar'25 | N2: YTD Apr'25 | O2: YTD May'25 | P2: YTD Jun'25
A3: A- Total Income
A4: Revenue from operations | B4: 1 | C4: ='Notes to P&L'!$B$13 -> 110109.4 | D4: ='Notes to P&L'!C13 -> 109935 | E4: ='Notes to P&L'!D13 -> 116566.58 | F4: ='Notes to P&L'!E13 -> 110770.69 | G4: ='Notes to P&L'!F13 -> 118799.9 | H4: ='Notes to P&L'!G13 -> 109395.31 | K4: ='Notes to P&L'!$B$13 -> 110109.4 | L4: =K4+D4 -> 220044.4 | M4: =L4+E4 -> 336610.98 | N4: =M4+F4 -> 447381.67 | O4: =N4+G4 -> 566181.57 | P4: =O4+H4 -> 675576.87
A5: Other income | B5: 2 | C5: ='Notes to P&L'!$B$20 -> 255 | D5: ='Notes to P&L'!C20 -> 168.735 | E5: ='Notes to P&L'!D20 -> 296.047 | F5: ='Notes to P&L'!E20 -> 2703.018 | G5: ='Notes to P&L'!F20 -> 0 | H5: ='Notes to P&L'!G20 -> 0 | K5: ='Notes to P&L'!$B$20 -> 255 | L5: =K5+D5 -> 423.735 | M5: =L5+E5 -> 719.782 | N5: =M5+F5 -> 3422.8 | O5: =N5+G5 -> 3422.8 | P5: =O5+H5 -> 3422.8
A6: Total Income | C6: =C4+C5 -> 110364.4 | D6: =D4+D5 -> 110103.74 | E6: =E4+E5 -> 116862.63 | F6: =F4+F5 -> 113473.7 | G6: =G4+G5 -> 118799.9 | H6: =H4+H5 -> 109395.31 | K6: =K4+K5 -> 110364.4 | L6: =L4+L5 -> 220468.13 | M6: =M4+M5 -> 337330.76 | N6: =N4+N5 -> 450804.47 | O6: =O4+O5 -> 569604.37 | P6: =P4+P5 -> 678999.67
A7: B- Total Expenses
A8: Cost of raw material consumed | B8: 3 | C8: ='Notes to P&L'!$B$25 -> -60541.051 | D8: ='Notes to P&L'!C25 -> -73160.038 | E8: ='Notes to P&L'!D25 -> -83364.498 | F8: ='Notes to P&L'!E25 -> -70012.585 | G8: ='Notes to P&L'!F25 -> -56738.184 | H8: ='Notes to P&L'!G25 -> -65272.653 | K8: ='Notes to P&L'!$B$25 -> -60541.051 | L8: =K8+D8 -> -133701.09 | M8: =L8+E8 -> -217065.59 | N8: =M8+F8 -> -287078.17 | O8: =N8+G8 -> -343816.36 | P8: =O8+H8 -> -409089.01
A9: Changes in inventories of finished goods and work-in-progress | B9: 4 | C9: ='Notes to P&L'!$B$29 -> 1596.3599 | D9: ='Notes to P&L'!C29 -> 428.39589 | E9: ='Notes to P&L'!D29 -> 13096.192 | F9: ='Notes to P&L'!E29 -> 5134.8279 | G9: ='Notes to P&L'!F29 -> -24324.983 | H9: ='Notes to P&L'!G29 -> 1493.1106 | K9: ='Notes to P&L'!$B$29 -> 1596.3599 | L9: =K9+D9 -> 2024.7558 | M9: =L9+E9 -> 15120.947 | N9: =M9+F9 -> 20255.775 | O9: =N9+G9 -> -4069.2079 | P9: =O9+H9 -> -2576.0973
A10: Employee benefits expense | B10: 5 | C10: ='Notes to P&L'!$B$36 -> -19017.893 | D10: ='Notes to P&L'!C36 -> -17609.284 | E10: ='Notes to P&L'!D36 -> -26571.806 | F10: ='Notes to P&L'!E36 -> -25293.841 | G10: ='Notes to P&L'!F36 -> -21898.684 | H10: ='Notes to P&L'!G36 -> -19233.911 | K10: ='Notes to P&L'!$B$36 -> -19017.893 | L10: =K10+D10 -> -36627.178 | M10: =L10+E10 -> -63198.984 | N10: =M10+F10 -> -88492.825 | O10: =N10+G10 -> -110391.51 | P10: =O10+H10 -> -129625.42
A11: Finance costs | B11: 6 | C11: ='Notes to P&L'!$B$44 -> 0 | D11: ='Notes to P&L'!$B$44 -> 0 | E11: ='Notes to P&L'!$B$44 -> 0 | F11: ='Notes to P&L'!$B$44 -> 0 | G11: ='Notes to P&L'!$B$44 -> 0 | H11: ='Notes to P&L'!$B$44 -> 0 | K11: ='Notes to P&L'!$B$44 -> 0 | L11: =K11+D11 -> 0 | M11: =L11+E11 -> 0 | N11: =M11+F11 -> 0 | O11: =N11+G11 -> 0 | P11: =O11+H11 -> 0
A12: Depreciation and amortisation expenses | B12: 7 | C12: ='Notes to P&L'!$B$50 -> -2977.5528 | D12: ='Notes to P&L'!C50 -> -2736.5834 | E12: ='Notes to P&L'!D50 -> 457.03944 | F12: ='Notes to P&L'!E50 -> -6048.916 | G12: ='Notes to P&L'!F50 -> -3057.3774 | H12: ='Notes to P&L'!G50 -> -5915.07 | K12: ='Notes to P&L'!$B$50 -> -2977.5528 | L12: =K12+D12 -> -5714.1362 | M12: =L12+E12 -> -5257.0968 | N12: =M12+F12 -> -11306.013 | O12: =N12+G12 -> -14363.39 | P12: =O12+H12 -> -20278.46
A13: Other expenses | B13: 8 | C13: ='Notes to P&L'!$B$79 -> -11389.642 | D13: ='Notes to P&L'!C79 -> -10083.024 | E13: ='Notes to P&L'!D79 -> -14158.488 | F13: ='Notes to P&L'!E79 -> -11855.779 | G13: ='Notes to P&L'!F79 -> -12055.6 | H13: ='Notes to P&L'!G79 -> -12265.818 | K13: ='Notes to P&L'!$B$79 -> -11389.642 | L13: =K13+D13 -> -21472.666 | M13: =L13+E13 -> -35631.154 | N13: =M13+F13 -> -47486.933 | O13: =N13+G13 -> -59542.534 | P13: =O13+H13 -> -71808.352
A14: Total expenses | C14: =SUM(C8:C13) -> -92329.779 | D14: =SUM(D8:D13) -> -103160.53 | E14: =SUM(E8:E13) -> -110541.56 | F14: =SUM(F8:F13) -> -108076.29 | G14: =SUM(G8:G13) -> -118074.83 | H14: =SUM(H8:H13) -> -101194.34 | K14: =SUM(K8:K13) -> -92329.779 | L14: =SUM(L8:L13) -> -195490.31 | M14: =SUM(M8:M13) -> -306031.87 | N14: =SUM(N8:N13) -> -414108.17 | O14: =SUM(O8:O13) -> -532183 | P14: =SUM(P8:P13) -> -633377.34
A15: Profit before tax (EBIT) | C15: =C6+C14 -> 18034.619 | D15: =D6+D14 -> 6943.2034 | E15: =E6+E14 -> 6321.068 | F15: =F6+F14 -> 5397.4097 | G15: =G6+G14 -> 725.07147 | H15: =H6+H14 -> 8200.9639 | K15: =K6+K14 -> 18034.619 | L15: =L6+L14 -> 24977.822 | M15: =M6+M14 -> 31298.89 | N15: =N6+N14 -> 36696.3 | O15: =O6+O14 -> 37421.371 | P15: =P6+P14 -> 45622.335
A16: Current tax | C16: ='Notes to P&L'!$B$83 -> -4690.7602 | D16: ='Notes to P&L'!C83 -> -1805.3967 | E16: ='Notes to P&L'!D83 -> -1646.7086 | F16: ='Notes to P&L'!E83 -> -1405.3944 | G16: ='Notes to P&L'!F83 -> -190.54658 | H16: ='Notes to P&L'!G83 -> -1967.0086 | K16: ='Notes to P&L'!$B$83 -> -4690.7602 | L16: =K16+D16 -> -6496.1569 | M16: =L16+E16 -> -8142.8655 | N16: =M16+F16 -> -9548.2599 | O16: =N16+G16 -> -9738.8065 | P16: =O16+H16 -> -11705.815
A17: Deferred tax | C17: 0 | D17: 0 | E17: 0 | F17: 0 | G17: 0 | H17: 0 | K17: 0 | L17: =K17+D17 -> 0 | M17: =L17+E17 -> 0 | N17: =M17+F17 -> 0 | O17: =N17+G17 -> 0 | P17: =O17+H17 -> 0
A18: Profit for the year (PAT) | C18: =C15+C16 -> 13343.858 | D18: =D15+D16 -> 5137.8067 | E18: =E15+E16 -> 4674.3594 | F18: =F15+F16 -> 3992.0153 | G18: =G15+G16 -> 534.52489 | H18: =H15+H16 -> 6233.9553 | K18: =K15+K16 -> 13343.858 | L18: =L15+L16 -> 18481.665 | M18: =M15+M16 -> 23156.025 | N18: =N15+N16 -> 27148.04 | O18: =O15+O16 -> 27682.565 | P18: =P15+P16 -> 33916.52

Sheet Notes to P&L
A2: 1. Revenue from operations | B2: Jan'25 | C2: Feb'25 | D2: Mar'25 | E2: Apr'25 | F2: May'25 | G2: Jun'25 | I2: Jan'25 | J2: YTD Feb'25 | K2: YTD Mar'25 | L2: YTD Apr'25 | M2: YTD May'25 | N2: YTD Jun'25
A3: Particulars | B3: Amount T INR | C3: Amount T INR | D3: Amount T INR | E3: Amount T INR | F3: Amount T INR | G3: Amount T INR | I3: Amount T INR | J3: Amount T INR | K3: Amount T INR | L3: Amount T INR | M3: Amount T INR | N3: Amount T INR
A4: Sale of products | B4: =SUMIF('[1]P&L LocCur'!$A:$A,A4,'[1]P&L LocCur'!$V:$V) -> 110109.4 | C4: =SUMIF('[1]P&L LocCur'!$A:$A,A4,'[1]P&L LocCur'!$W:$W) -> 109935 | D4: =SUMIF('[1]P&L LocCur'!$A:$A,A4,'[1]P&L LocCur'!$X:$X) -> 116566.58 | E4: =SUMIF('[1]P&L LocCur'!$A:$A,A4,'[1]P&L LocCur'!$Y:$Y) -> 110770.69 | F4: =SUMIF('[1]P&L LocCur'!$A:$A,A4,'[1]P&L LocCur'!$Z:$Z) -> 118799.9 | G4: =SUMIF('[1]P&L LocCur'!$A:$A,A4,'[1]P&L LocCur'!$AA:$AA) -> 109395.31 | I4: =B4 -> 110109.4 | J4: =I4+C4 -> 220044.4 | K4: =J4+D4 -> 336610.98 | L4: =K4+E4 -> 447381.67 | M4: =L4+F4 -> 566181.57 | N4: =M4+G4 -> 675576.87
A5: Sale of services | B5: =SUMIF('[1]P&L LocCur'!$A:$A,A5,'[1]P&L LocCur'!$V:$V) -> 0 | C5: =SUMIF('[1]P&L LocCur'!$A:$A,A5,'[1]P&L LocCur'!$W:$W) -> 0 | D5: =SUMIF('[1]P&L LocCur'!$A:$A,A5,'[1]P&L LocCur'!$X:$X) -> 0 | E5: =SUMIF('[1]P&L LocCur'!$A:$A,A5,'[1]P&L LocCur'!$Y:$Y) -> 0 | F5: =SUMIF('[1]P&L LocCur'!$A:$A,A5,'[1]P&L LocCur'!$Z:$Z) -> 0 | G5: =SUMIF('[1]P&L LocCur'!$A:$A,A5,'[1]P&L LocCur'!$AA:$AA) -> 0 | I5: =B5 -> 0 | J5: =I5+C5 -> 0 | K5: =J5+D5 -> 0 | L5: =K5+E5 -> 0 | M5: =L5+F5 -> 0 | N5: =M5+G5 -> 0
A6: Sub Total | B6: =SUM(B4:B5) -> 110109.4 | C6: =SUM(C4:C5) -> 109935 | D6: =SUM(D4:D5) -> 116566.58 | E6: =SUM(E4:E5) -> 110770.69 | F6: =SUM(F4:F5) -> 118799.9 | G6: =SUM(G4:G5) -> 109395.31 | I6: =SUM(I4:I5) -> 110109.4 | J6: =SUM(J4:J5) -> 220044.4 | K6: =SUM(K4:K5) -> 336610.98 | L6: =SUM(L4:L5) -> 447381.67 | M6: =SUM(M4:M5) -> 566181.57 | N6: =SUM(N4:N5) -> 675576.87
A7: Other Operating revenues
A8: Scrap sales | B8: =SUMIF('[1]P&L LocCur'!$A:$A,A8,'[1]P&L LocCur'!$V:$V) -> 0 | C8: =SUMIF('[1]P&L LocCur'!$A:$A,A8,'[1]P&L LocCur'!$W:$W) -> 0 | D8: =SUMIF('[1]P&L LocCur'!$A:$A,A8,'[1]P&L LocCur'!$X:$X) -> 0 | E8: =SUMIF('[1]P&L LocCur'!$A:$A,A8,'[1]P&L LocCur'!$Y:$Y) -> 0 | F8: =SUMIF('[1]P&L LocCur'!$A:$A,A8,'[1]P&L LocCur'!$Z:$Z) -> 0 | G8: =SUMIF('[1]P&L LocCur'!$A:$A,A8,'[1]P&L LocCur'!$AA:$AA) -> 0 | I8: =B8 -> 0 | J8: =I8+C8 -> 0 | K8: =J8+D8 -> 0 | L8: =K8+E8 -> 0 | M8: =L8+F8 -> 0 | N8: =M8+G8 -> 0
A9: Tooling income | B9: =SUMIF('[1]P&L LocCur'!$A:$A,A9,'[1]P&L LocCur'!$V:$V) -> 0 | C9: =SUMIF('[1]P&L LocCur'!$A:$A,A9,'[1]P&L LocCur'!$W:$W) -> 0 | D9: =SUMIF('[1]P&L LocCur'!$A:$A,A9,'[1]P&L LocCur'!$X:$X) -> 0 | E9: =SUMIF('[1]P&L LocCur'!$A:$A,A9,'[1]P&L LocCur'!$Y:$Y) -> 0 | F9: =SUMIF('[1]P&L LocCur'!$A:$A,A9,'[1]P&L LocCur'!$Z:$Z) -> 0 | G9: =SUMIF('[1]P&L LocCur'!$A:$A,A9,'[1]P&L LocCur'!$AA:$AA) -> 0 | I9: =B9 -> 0 | J9: =I9+C9 -> 0 | K9: =J9+D9 -> 0 | L9: =K9+E9 -> 0 | M9: =L9+F9 -> 0 | N9: =M9+G9 -> 0
A10: Export incentive benefits | B10: =SUMIF('[1]P&L LocCur'!$A:$A,A10,'[1]P&L LocCur'!$V:$V) -> 0 | C10: =SUMIF('[1]P&L LocCur'!$A:$A,A10,'[1]P&L LocCur'!$W:$W) -> 0 | D10: =SUMIF('[1]P&L LocCur'!$A:$A,A10,'[1]P&L LocCur'!$X:$X) -> 0 | E10: =SUMIF('[1]P&L LocCur'!$A:$A,A10,'[1]P&L LocCur'!$Y:$Y) -> 0 | F10: =SUMIF('[1]P&L LocCur'!$A:$A,A10,'[1]P&L LocCur'!$Z:$Z) -> 0 | G10: =SUMIF('[1]P&L LocCur'!$A:$A,A10,'[1]P&L LocCur'!$AA:$AA) -> 0 | I10: =B10 -> 0 | J10: =I10+C10 -> 0 | K10: =J10+D10 -> 0 | L10: =K10+E10 -> 0 | M10: =L10+F10 -> 0 | N10: =M10+G10 -> 0
A11: Income from government grants | B11: =SUMIF('[1]P&L LocCur'!$A:$A,A11,'[1]P&L LocCur'!$V:$V) -> 0 | C11: =SUMIF('[1]P&L LocCur'!$A:$A,A11,'[1]P&L LocCur'!$W:$W) -> 0 | D11: =SUMIF('[1]P&L LocCur'!$A:$A,A11,'[1]P&L LocCur'!$X:$X) -> 0 | E11: =SUMIF('[1]P&L LocCur'!$A:$A,A11,'[1]P&L LocCur'!$Y:$Y) -> 0 | F11: =SUMIF('[1]P&L LocCur'!$A:$A,A11,'[1]P&L LocCur'!$Z:$Z) -> 0 | G11: =SUMIF('[1]P&L LocCur'!$A:$A,A11,'[1]P&L LocCur'!$AA:$AA) -> 0 | I11: =B11 -> 0 | J11: =I11+C11 -> 0 | K11: =J11+D11 -> 0 | L11: =K11+E11 -> 0 | M11: =L11+F11 -> 0 | N11: =M11+G11 -> 0
A12: Sale of child parts | B12: =SUMIF('[1]P&L LocCur'!$A:$A,A12,'[1]P&L LocCur'!$V:$V) -> 0 | C12: =SUMIF('[1]P&L LocCur'!$A:$A,A12,'[1]P&L LocCur'!$W:$W) -> 0 | D12: =SUMIF('[1]P&L LocCur'!$A:$A,A12,'[1]P&L LocCur'!$X:$X) -> 0 | E12: =SUMIF('[1]P&L LocCur'!$A:$A,A12,'[1]P&L LocCur'!$Y:$Y) -> 0 | F12: =SUMIF('[1]P&L LocCur'!$A:$A,A12,'[1]P&L LocCur'!$Z:$Z) -> 0 | G12: =SUMIF('[1]P&L LocCur'!$A:$A,A12,'[1]P&L LocCur'!$AA:$AA) -> 0 | I12: =B12 -> 0 | J12: =I12+C12 -> 0 | K12: =J12+D12 -> 0 | L12: =K12+E12 -> 0 | M12: =L12+F12 -> 0 | N12: =M12+G12 -> 0
A13: Total | B13: =B6+SUM(B8:B12) -> 110109.4 | C13: =C6+SUM(C8:C12) -> 109935 | D13: =D6+SUM(D8:D12) -> 116566.58 | E13: =E6+SUM(E8:E12) -> 110770.69 | F13: =F6+SUM(F8:F12) -> 118799.9 | G13: =G6+SUM(G8:G12) -> 109395.31 | I13: =I6+SUM(I8:I12) -> 110109.4 | J13: =J6+SUM(J8:J12) -> 220044.4 | K13: =K6+SUM(K8:K12) -> 336610.98 | L13: =L6+SUM(L8:L12) -> 447381.67 | M13: =M6+SUM(M8:M12) -> 566181.57 | N13: =N6+SUM(N8:N12) -> 675576.87
A15: 2. Other Income
A16: Particulars
A17: Interest income on bank deposits | B17: =SUMIF('[1]P&L LocCur'!$A:$A,A17,'[1]P&L LocCur'!$V:$V) -> 0 | C17: =SUMIF('[1]P&L LocCur'!$A:$A,A17,'[1]P&L LocCur'!$W:$W) -> 0 | D17: =SUMIF('[1]P&L LocCur'!$A:$A,A17,'[1]P&L LocCur'!$X:$X) -> 0 | E17: =SUMIF('[1]P&L LocCur'!$A:$A,A17,'[1]P&L LocCur'!$Y:$Y) -> 0 | F17: =SUMIF('[1]P&L LocCur'!$A:$A,A17,'[1]P&L LocCur'!$Z:$Z) -> 0 | G17: =SUMIF('[1]P&L LocCur'!$A:$A,A17,'[1]P&L LocCur'!$AA:$AA) -> 0 | I17: =B17 -> 0 | J17: =I17+C17 -> 0 | K17: =J17+D17 -> 0 | L17: =K17+E17 -> 0 | M17: =L17+F17 -> 0 | N17: =M17+G17 -> 0
A18: Net foreign exchange gain | B18: =SUMIF('[1]P&L LocCur'!$A:$A,A18,'[1]P&L LocCur'!$V:$V) -> 0 | C18: =SUMIF('[1]P&L LocCur'!$A:$A,A18,'[1]P&L LocCur'!$W:$W) -> 0 | D18: =SUMIF('[1]P&L LocCur'!$A:$A,A18,'[1]P&L LocCur'!$X:$X) -> 0 | E18: =SUMIF('[1]P&L LocCur'!$A:$A,A18,'[1]P&L LocCur'!$Y:$Y) -> 0 | F18: =SUMIF('[1]P&L LocCur'!$A:$A,A18,'[1]P&L LocCur'!$Z:$Z) -> 0 | G18: =SUMIF('[1]P&L LocCur'!$A:$A,A18,'[1]P&L LocCur'!$AA:$AA) -> 0 | I18: =B18 -> 0 | J18: =I18+C18 -> 0 | K18: =J18+D18 -> 0 | L18: =K18+E18 -> 0 | M18: =L18+F18 -> 0 | N18: =M18+G18 -> 0
A19: Other Income | B19: 255 | C19: =SUMIF('[1]P&L LocCur'!$A:$A,A19,'[1]P&L LocCur'!$W:$W) -> 168.735 | D19: =SUMIF('[1]P&L LocCur'!$A:$A,A19,'[1]P&L LocCur'!$X:$X) -> 296.047 | E19: =SUMIF('[1]P&L LocCur'!$A:$A,A19,'[1]P&L LocCur'!$Y:$Y) -> 2703.018 | F19: =SUMIF('[1]P&L LocCur'!$A:$A,A19,'[1]P&L LocCur'!$Z:$Z) -> 0 | G19: =SUMIF('[1]P&L LocCur'!$A:$A,A19,'[1]P&L LocCur'!$AA:$AA) -> 0 | I19: =B19 -> 255 | J19: =I19+C19 -> 423.735 | K19: =J19+D19 -> 719.782 | L19: =K19+E19 -> 3422.8 | M19: =L19+F19 -> 3422.8 | N19: =M19+G19 -> 3422.8
A20: Total | B20: =SUM(B17:B19) -> 255 | C20: =SUM(C17:C19) -> 168.735 | D20: =SUM(D17:D19) -> 296.047 | E20: =SUM(E17:E19) -> 2703.018 | F20: =SUM(F17:F19) -> 0 | G20: =SUM(G17:G19) -> 0 | I20: =SUM(I17:I19) -> 255 | J20: =SUM(J17:J19) -> 423.735 | K20: =SUM(K17:K19) -> 719.782 | L20: =SUM(L17:L19) -> 3422.8 | M20: =SUM(M17:M19) -> 3422.8 | N20: =SUM(N17:N19) -> 3422.8
A22: 3. Cost of Raw material comsumed
A23: Particulars
A24: Cost of Raw material consumed | B24: =SUMIF('[1]P&L LocCur'!$A:$A,A24,'[1]P&L LocCur'!$V:$V) -> -60541.051 | C24: =SUMIF('[1]P&L LocCur'!$A:$A,A24,'[1]P&L LocCur'!$W:$W) -> -73160.038 | D24: =SUMIF('[1]P&L LocCur'!$A:$A,A24,'[1]P&L LocCur'!$X:$X) -> -83364.498 | E24: =SUMIF('[1]P&L LocCur'!$A:$A,A24,'[1]P&L LocCur'!$Y:$Y) -> -70012.585 | F24: =SUMIF('[1]P&L LocCur'!$A:$A,A24,'[1]P&L LocCur'!$Z:$Z) -> -56738.184 | G24: =SUMIF('[1]P&L LocCur'!$A:$A,A24,'[1]P&L LocCur'!$AA:$AA) -> -65272.653 | I24: =B24 -> -60541.051 | J24: =I24+C24 -> -133701.09 | K24: =J24+D24 -> -217065.59 | L24: =K24+E24 -> -287078.17 | M24: =L24+F24 -> -343816.36 | N24: =M24+G24 -> -409089.01
A25: Total | B25: =SUM(B24) -> -60541.051 | C25: =SUM(C24) -> -73160.038 | D25: =SUM(D24) -> -83364.498 | E25: =SUM(E24) -> -70012.585 | F25: =SUM(F24) -> -56738.184 | G25: =SUM(G24) -> -65272.653 | I25: =SUM(I24) -> -60541.051 | J25: =SUM(J24) -> -133701.09 | K25: =SUM(K24) -> -217065.59 | L25: =SUM(L24) -> -287078.17 | M25: =SUM(M24) -> -343816.36 | N25: =SUM(N24) -> -409089.01
A27: 4.Changes in inventories of finished goods and work-in-progress
A28: Particulars
A29: Changes in inventories of finished goods and work-in-progress | B29: =SUMIF('[1]P&L LocCur'!$A:$A,A29,'[1]P&L LocCur'!$V:$V) -> 1596.3599 | C29: =SUMIF('[1]P&L LocCur'!$A:$A,A29,'[1]P&L LocCur'!$W:$W) -> 428.39589 | D29: =SUMIF('[1]P&L LocCur'!$A:$A,A29,'[1]P&L LocCur'!$X:$X) -> 13096.192 | E29: =SUMIF('[1]P&L LocCur'!$A:$A,A29,'[1]P&L LocCur'!$Y:$Y) -> 5134.8279 | F29: =SUMIF('[1]P&L LocCur'!$A:$A,A29,'[1]P&L LocCur'!$Z:$Z) -> -24324.983 | G29: =SUMIF('[1]P&L LocCur'!$A:$A,A29,'[1]P&L LocCur'!$AA:$AA) -> 1493.1106 | I29: =B29 -> 1596.3599 | J29: =I29+C29 -> 2024.7558 | K29: =J29+D29 -> 15120.947 | L29: =K29+E29 -> 20255.775 | M29: =L29+F29 -> -4069.2079 | N29: =M29+G29 -> -2576.0973
A31: 5.Employee benefits expense
A32: Particulars
A33: Salaries and wages | B33: =SUMIF('[1]P&L LocCur'!$A:$A,A33,'[1]P&L LocCur'!$V:$V) -> -19017.893 | C33: =SUMIF('[1]P&L LocCur'!$A:$A,A33,'[1]P&L LocCur'!$W:$W) -> -17609.284 | D33: =SUMIF('[1]P&L LocCur'!$A:$A,A33,'[1]P&L LocCur'!$X:$X) -> -26571.806 | E33: =SUMIF('[1]P&L LocCur'!$A:$A,A33,'[1]P&L LocCur'!$Y:$Y) -> -25293.841 | F33: =SUMIF('[1]P&L LocCur'!$A:$A,A33,'[1]P&L LocCur'!$Z:$Z) -> -21898.684 | G33: =SUMIF('[1]P&L LocCur'!$A:$A,A33,'[1]P&L LocCur'!$AA:$AA) -> -19233.911 | I33: =B33 -> -19017.893 | J33: =I33+C33 -> -36627.178 | K33: =J33+D33 -> -63198.984 | L33: =K33+E33 -> -88492.825 | M33: =L33+F33 -> -110391.51 | N33: =M33+G33 -> -129625.42
A34: Contribution to provident and other funds | B34: =SUMIF('[1]P&L LocCur'!$A:$A,A34,'[1]P&L LocCur'!$V:$V) -> 0 | C34: =SUMIF('[1]P&L LocCur'!$A:$A,A34,'[1]P&L LocCur'!$W:$W) -> 0 | D34: =SUMIF('[1]P&L LocCur'!$A:$A,A34,'[1]P&L LocCur'!$X:$X) -> 0 | E34: =SUMIF('[1]P&L LocCur'!$A:$A,A34,'[1]P&L LocCur'!$Y:$Y) -> 0 | F34: =SUMIF('[1]P&L LocCur'!$A:$A,A34,'[1]P&L LocCur'!$Z:$Z) -> 0 | G34: =SUMIF('[1]P&L LocCur'!$A:$A,A34,'[1]P&L LocCur'!$AA:$AA) -> 0 | I34: =B34 -> 0 | J34: =I34+C34 -> 0 | K34: =J34+D34 -> 0 | L34: =K34+E34 -> 0 | M34: =L34+F34 -> 0 | N34: =M34+G34 -> 0
A35: Staff welfare expenses | B35: =SUMIF('[1]P&L LocCur'!$A:$A,A35,'[1]P&L LocCur'!$V:$V) -> 0 | C35: =SUMIF('[1]P&L LocCur'!$A:$A,A35,'[1]P&L LocCur'!$W:$W) -> 0 | D35: =SUMIF('[1]P&L LocCur'!$A:$A,A35,'[1]P&L LocCur'!$X:$X) -> 0 | E35: =SUMIF('[1]P&L LocCur'!$A:$A,A35,'[1]P&L LocCur'!$Y:$Y) -> 0 | F35: =SUMIF('[1]P&L LocCur'!$A:$A,A35,'[1]P&L LocCur'!$Z:$Z) -> 0 | G35: =SUMIF('[1]P&L LocCur'!$A:$A,A35,'[1]P&L LocCur'!$AA:$AA) -> 0 | I35: =B35 -> 0 | J35: =I35+C35 -> 0 | K35: =J35+D35 -> 0 | L35: =K35+E35 -> 0 | M35: =L35+F35 -> 0 | N35: =M35+G35 -> 0
A36: Total | B36: =SUM(B33:B35) -> -19017.893 | C36: =SUM(C33:C35) -> -17609.284 | D36: =SUM(D33:D35) -> -26571.806 | E36: =SUM(E33:E35) -> -25293.841 | F36: =SUM(F33:F35) -> -21898.684 | G36: =SUM(G33:G35) -> -19233.911 | I36: =SUM(I33:I35) -> -19017.893 | J36: =SUM(J33:J35) -> -36627.178 | K36: =SUM(K33:K35) -> -63198.984 | L36: =SUM(L33:L35) -> -88492.825 | M36: =SUM(M33:M35) -> -110391.51 | N36: =SUM(N33:N35) -> -129625.42
A38: 6.Finance costs
A39: Particulars
A40: Interest expense on
A41: - Banks and Financial institution borrowings | B41: =SUMIF('[1]P&L LocCur'!$A:$A,A41,'[1]P&L LocCur'!$V:$V) -> 0 | C41: =SUMIF('[1]P&L LocCur'!$A:$A,A41,'[1]P&L LocCur'!$W:$W) -> 0 | D41: =SUMIF('[1]P&L LocCur'!$A:$A,A41,'[1]P&L LocCur'!$X:$X) -> 0 | E41: =SUMIF('[1]P&L LocCur'!$A:$A,A41,'[1]P&L LocCur'!$Y:$Y) -> 0 | F41: =SUMIF('[1]P&L LocCur'!$A:$A,A41,'[1]P&L LocCur'!$Z:$Z) -> 0 | G41: =SUMIF('[1]P&L LocCur'!$A:$A,A41,'[1]P&L LocCur'!$AA:$AA) -> 0 | I41: =B41 -> 0 | J41: =I41+C41 -> 0 | K41: =J41+D41 -> 0 | L41: =K41+E41 -> 0 | M41: =L41+F41 -> 0 | N41: =M41+G41 -> 0
A42: - Others | B42: =SUMIF('[1]P&L LocCur'!$A:$A,A42,'[1]P&L LocCur'!$V:$V) -> 0 | C42: =SUMIF('[1]P&L LocCur'!$A:$A,A42,'[1]P&L LocCur'!$W:$W) -> 0 | D42: =SUMIF('[1]P&L LocCur'!$A:$A,A42,'[1]P&L LocCur'!$X:$X) -> 0 | E42: =SUMIF('[1]P&L LocCur'!$A:$A,A42,'[1]P&L LocCur'!$Y:$Y) -> 0 | F42: =SUMIF('[1]P&L LocCur'!$A:$A,A42,'[1]P&L LocCur'!$Z:$Z) -> 0 | G42: =SUMIF('[1]P&L LocCur'!$A:$A,A42,'[1]P&L LocCur'!$AA:$AA) -> 0 | I42: =B42 -> 0 | J42: =I42+C42 -> 0 | K42: =J42+D42 -> 0 | L42: =K42+E42 -> 0 | M42: =L42+F42 -> 0 | N42: =M42+G42 -> 0
A43: Interest on obligations under lease | B43: =SUMIF('[1]P&L LocCur'!$A:$A,A43,'[1]P&L LocCur'!$V:$V) -> 0 | C43: =SUMIF('[1]P&L LocCur'!$A:$A,A43,'[1]P&L LocCur'!$W:$W) -> 0 | D43: =SUMIF('[1]P&L LocCur'!$A:$A,A43,'[1]P&L LocCur'!$X:$X) -> 0 | E43: =SUMIF('[1]P&L LocCur'!$A:$A,A43,'[1]P&L LocCur'!$Y:$Y) -> 0 | F43: =SUMIF('[1]P&L LocCur'!$A:$A,A43,'[1]P&L LocCur'!$Z:$Z) -> 0 | G43: =SUMIF('[1]P&L LocCur'!$A:$A,A43,'[1]P&L LocCur'!$AA:$AA) -> 0 | I43: =B43 -> 0 | J43: =I43+C43 -> 0 | K43: =J43+D43 -> 0 | L43: =K43+E43 -> 0 | M43: =L43+F43 -> 0 | N43: =M43+G43 -> 0
A44: Total | B44: =SUM(B41:B43) -> 0 | C44: =SUM(C41:C43) -> 0 | D44: =SUM(D41:D43) -> 0 | E44: =SUM(E41:E43) -> 0 | F44: =SUM(F41:F43) -> 0 | G44: =SUM(G41:G43) -> 0 | I44: =SUM(I41:I43) -> 0 | J44: =SUM(J41:J43) -> 0 | K44: =SUM(K41:K43) -> 0 | L44: =SUM(L41:L43) -> 0 | M44: =SUM(M41:M43) -> 0 | N44: =SUM(N41:N43) -> 0
A46: 7.Depreciation and amortisation expenses
A47: Particulars
...

Sheet Sheet1

Sheet BS
A1: Balance sheet as on March 2025
A2: A -Total Liabilities | B2: Amount INR
A3: Equity Capital | B3: 200000
A4: Reserves | B4: 500000
A5: Borrowings - | B5: =SUM(B6:B9) -> 400000
A6: Long term Borrowings | B6: 200000
A7: Short term Borrowings | B7: 100000
A8: Lease Liabilities | B8: 90000
A9: Other Borrowings | B9: 10000
A10: Other Liabilities - | B10: =SUM(B11:B13) -> 300000
A11: Trade Payables | B11: 100000
A12: Advance from Customers | B12: 50000
A13: Other liability items | B13: 150000
A14: Total Liabilities | B14: =B3+B4+B5+B10 -> 1400000
A15: B -Total Assets
A16: Fixed Assets - | B16: =SUM(B17:B25)-B27 -> 1000000
A17: Land | B17: 200000
A18: Building | B18: 140000
A19: Plant Machinery | B19: 800000
A20: Equipments | B20: 10000
A21: Computers | B21: 10000
A22: Furniture n fittings | B22: 10000
A23: Vehicles | B23: 10000
A24: Intangible Assets | B24: 10000
A25: Other fixed assets | B25: 10000
A26: Gross Block | B26: =SUM(B17:B25) -> 1200000
A27: Accumulated Depreciation | B27: 200000
A28: CWIP | B28: 50000
A29: Investments | B29: 20000
A30: Other Assets - | B30: =SUM(B31:B35) -> 330000
A31: Inventories | B31: 100000
A32: Trade receivables | B32: =(250-70)*1000 -> 180000
A33: Cash Equivalents | B33: 20000
A34: Loans & Advances | B34: 10000
A35: Other asset items | B35: 20000
A36: Total Assets | B36: =B16+B28+B29+B30 -> 1400000
A38: Working Capital | B38: =B31+B32-B11 -> 180000
